Workbook

Sheet README
A1: Inventory & IT Asset Control Toolkit
A2: Version: v1.0.0 | Author: Daniel A. Cruz
A3: Disclaimer: All data in this workbook is fictional sample data created for demonstration and interview purposes. No real company, customer, or employee information is represented.
A5: Purpose of This Workbook
A6: This toolkit demonstrates a disciplined approach to inventory optimization and IT asset lifecycle control. It combines clean data capture, exception reporting, audit readiness, and management-level visibility in a single interview-ready workbook generated entirely from Python source code.
A8: Mavis / Inventory Optimization Demo Path
A9: Recommended tab order: 1. Inventory Dashboard 2. Aged Excess Analysis 3. Transfer Planner 4. Markdown Planner 5. Management Summary Suggested narrative: "This section focuses on inventory optimization. The dashboard shows inventory value, aged stock, excess inventory, transfer candidates, markdown candidates, and estimated recovery value. From there, I drill into aged and excess inventory, evaluate whether a transfer should happen before markdown, and use the markdown planner to protect margin while exiting slow-moving inventory."
A11: IT Inventory Control Demo Path
A12: Recommended tab order: 1. IT Asset Register 2. Audit Reconciliation 3. Software Licenses 4. Mobile Provisioning 5. Disposal Log 6. Management Summary Suggested narrative: "This section focuses on IT asset lifecycle control. The asset register tracks equipment from receipt through assignment, audit, return, repair, data wipe, and disposal. Audit reconciliation compares system inventory against physical audit results and flags exceptions. The license tracker and mobile provisioning tabs help standardize compliance and equipment control."
A14: Key Capabilities
A15: Inventory & Supply Chain • Inventory health dashboards with KPI cards and charts • Aged, excess, slow-moving, and obsolete stock analysis • Transfer planning between locations to balance stock • Markdown modeling to protect margin on end-of-life inventory IT Asset Control • Full lifecycle asset register from receipt through disposal • Physical audit reconciliation with exception reporting • Software license compliance and renewal risk tracking • Mobile provisioning and recovery checklists • Disposal log with data wipe and certificate tracking Reporting • Printable management summary for leadership review • Conditional formatting to highlight operational risk • Filterable tables, formulas, and professional styling throughout
A17: Recommended Interview Talking Points
... A21: Use the sheet tabs at the bottom to move between modules. Start with the demo path that matches your interview focus, then close with Management Summary. All operational tabs include filterable headers — click the dropdown arrows to explore by status, location, or department.

Sheet Master Inventory
A1: Master Inventory — 120 SKU-Location Records
A2: Item ID | B2: SKU | C2: Product Name | D2: Category | E2: Subcategory | F2: Location | G2: Location Type | H2: Region | I2: Quantity On Hand | J2: Min Stock | K2: Max Stock | L2: Unit Cost | M2: Selling Price | N2: Total Value | O2: Last Movement Date | P2: Last Sale Date | Q2: Age Days | R2: 90 Day Demand | S2: Sell Through Rate | T2: Gross Margin % | U2: Status | V2: Recommended Action
A3: INV-00001 | B3: T-1001 | C3: Mavis Sport Grip 245/40R18 | D3: Tires | E3: Performance | F3: DC-NJ | G3: Distribution Center | H3: Northeast | I3: 3 | J3: 12 | K3: 48 | L3: 127.91 | M3: 189.52 | N3: 383.73 | O3: 46179 | P3: 46185 | Q3: 25 | R3: 18 | S3: 0.8571 | T3: 0.3251 | U3: Stockout Risk | V3: Replenish
A4: INV-00002 | B4: T-1002 | C4: Mavis SnowTrack 205/55R16 | D4: Tires | E4: Winter | F4: DC-PA | G4: Distribution Center | H4: Northeast | I4: 22 | J4: 8 | K4: 40 | L4: 100.7 | M4: 138.79 | N4: 2215.4 | O4: 45794 | P4: 45806 | Q4: 410 | R4: 0 | S4: 0 | T4: 0.2744 | U4: Obsolete | V4: Liquidate
A5: INV-00003 | B5: T-1003 | C5: Mavis Fleet HD 225/75R16 | D5: Tires | E5: Commercial | F5: Store-Bronx | G5: Retail Store | H5: NYC Metro | I5: 85 | J5: 10 | K5: 35 | L5: 148.75 | M5: 234.78 | N5: 12643.75 | O5: 45959 | P5: 45969 | Q5: 245 | R5: 6 | S5: 0.0659 | T5: 0.3664 | U5: Excess / Aged | V5: Transfer or Markdown
A6: INV-00004 | B6: BP-1004 | C6: Ceramic Brake Pad Set - Front | D6: Brake Parts | E6: Pads | F6: Store-Queens | G6: Retail Store | H6: NYC Metro | I6: 72 | J6: 10 | K6: 35 | L6: 32.98 | M6: 48.98 | N6: 2374.56 | O6: 46109 | P6: 46120 | Q6: 95 | R6: 14 | S6: 0.1628 | T6: 0.3267 | U6: Excess | V6: Review Transfer
A7: INV-00005 | B7: BP-1005 | C7: Vented Brake Rotor 11.8in | D7: Brake Parts | E7: Rotors | F7: Store-Brooklyn | G7: Retail Store | H7: NYC Metro | I7: 28 | J7: 10 | K7: 40 | L7: 48.27 | M7: 78.58 | N7: 1351.56 | O7: 45994 | P7: 46005 | Q7: 210 | R7: 2 | S7: 0.0667 | T7: 0.3857 | U7: Slow-Moving | V7: Markdown Review
A8: INV-00006 | B8: BP-1006 | C8: Reman Brake Caliper - Rear | D8: Brake Parts | E8: Calipers | F8: Store-Manhattan | G8: Retail Store | H8: NYC Metro | I8: 24 | J8: 10 | K8: 45 | L8: 74.84 | M8: 110.99 | N8: 1796.16 | O8: 46164 | P8: 46173 | Q8: 40 | R8: 22 | S8: 0.4783 | T8: 0.3257 | U8: Healthy | V8: Monitor
A9: INV-00007 | B9: F-1007 | C9: Cabin Air Filter CF-1180 | D9: Filters | E9: Cabin | F9: DC-PA | G9: Distribution Center | H9: Northeast | I9: 66 | J9: 9 | K9: 40 | L9: 16.72 | M9: 26.37 | N9: 1103.52 | O9: 46173 | P9: 46185 | Q9: 31 | R9: 30 | S9: 0.3125 | T9: 0.3659 | U9: Excess | V9: Review Transfer
A10: INV-00008 | B10: T-1008 | C10: Impact Wrench 1/2in 20V | D10: Tools | E10: Power Tools | F10: Store-Bronx | G10: Retail Store | H10: NYC Metro | I10: 38 | J10: 8 | K10: 52 | L10: 192.92 | M10: 287.45 | N10: 7330.96 | O10: 45829 | P10: 45840 | Q10: 375 | R10: 23 | S10: 0.377 | T10: 0.3289 | U10: Healthy | V10: Monitor
A11: INV-00009 | B11: F-1009 | C11: Inline Fuel Filter FF-330 | D11: Filters | E11: Fuel | F11: DC-NY | G11: Distribution Center | H11: Northeast | I11: 51 | J11: 15 | K11: 34 | L11: 12.46 | M11: 18.04 | N11: 635.46 | O11: 45916 | P11: 45927 | Q11: 288 | R11: 32 | S11: 0.3855 | T11: 0.3093 | U11: Excess / Aged | V11: Transfer or Markdown
A12: INV-00010 | B12: A-1010 | C12: Beam Wiper Blade 22in | D12: Accessories | E12: Wipers | F12: Store-Queens | G12: Retail Store | H12: NYC Metro | I12: 57 | J12: 8 | K12: 37 | L12: 19.94 | M12: 28.28 | N12: 1136.58 | O12: 46121 | P12: 46122 | Q12: 83 | R12: 16 | S12: 0.2192 | T12: 0.2949 | U12: Excess | V12: Review Transfer
A13: INV-00011 | B13: F-1011 | C13: DOT 4 Brake Fluid 12oz | D13: Fluids | E13: Brake Fluid | F13: Store-WhitePlains | G13: Retail Store | H13: NYC Metro | I13: 13 | J13: 20 | K13: 48 | L13: 6.13 | M13: 9.81 | N13: 79.69 | O13: 45854 | P13: 45864 | Q13: 350 | R13: 22 | S13: 0.6286 | T13: 0.3751 | U13: Stockout Risk | V13: Replenish
A14: INV-00012 | B14: F-1012 | C14: Engine Air Filter AF-9921 | D14: Filters | E14: Air | F14: Store-Yonkers | G14: Retail Store | H14: NYC Metro | I14: 70 | J14: 18 | K14: 44 | L14: 13.69 | M14: 19.3 | N14: 958.3 | O14: 46080 | P14: 46090 | Q14: 124 | R14: 8 | S14: 0.1026 | T14: 0.2907 | U14: Excess | V14: Review Transfer
... A122: INV-00120 | B122: F-1120 | C122: Extended Life Coolant 1gal | D122: Fluids | E122: Coolant | F122: Store-Bronx | G122: Retail Store | H122: NYC Metro | I122: 29 | J122: 19 | K122: 61 | L122: 18.67 | M122: 28.86 | N122: 541.43 | O122: 45980 | P122: 45991 | Q122: 224 | R122: 34 | S122: 0.5397 | T122: 0.3531 | U122: Healthy | V122: Monitor

Sheet Inventory Dashboard
A1: Inventory Dashboard
A2: Key Performance Indicators
A3: Total Inventory Value | C3: Aged Inventory Value | E3: Excess Inventory Value | G3: Slow-Moving SKU Count | I3: Obsolete SKU Count
A4: =SUM('Master Inventory'!N3:N122) | C4: =SUMIF('Master Inventory'!Q3:Q122,">180",'Master Inventory'!N3:N122) | E4: =SUMIF('Master Inventory'!U3:U122,"Excess",'Master Inventory'!N3:N122)+SUMIF('Master Inventory'!U3:U122,"Excess / Aged",'Master Inventory'!N3:N122) | G4: =COUNTIF('Master Inventory'!U3:U122,"Slow-Moving") | I4: =COUNTIF('Master Inventory'!U3:U122,"Obsolete")
A6: Transfer Candidate Count | C6: Markdown Candidate Count | E6: Stockout Risk Count | G6: Estimated Recovery Value | I6: Average Gross Margin %
A7: =COUNTIF('Master Inventory'!V3:V122,"Review Transfer")+COUNTIF('Master Inventory'!V3:V122,"Transfer or Markdown") | C7: =COUNTIF('Master Inventory'!V3:V122,"Markdown Review")+COUNTIF('Master Inventory'!V3:V122,"Transfer or Markdown")+COUNTIF('Master Inventory'!V3:V122,"Liquidate") | E7: =COUNTIF('Master Inventory'!U3:U122,"Stockout Risk") | G7: =SUMIF('Master Inventory'!V3:V122,"Markdown Review",'Master Inventory'!N3:N122)+SUMIF('Master Inventory'!V3:V122,"Transfer or Markdown",'Master Inventory'!N3:N122)+SUMIF('Master Inventory'!V3:V122,"Liquidate",'Master Inventory'!N3:N122) | I7: =AVERAGE('Master Inventory'!T3:T122)
A9: Inventory Value by Location
A10: Location | B10: Inventory Value
A11: Store-Brooklyn | B11: 45168.37
A12: DC-NY | B12: 39471.92
A13: Store-Queens | B13: 37239.78
A14: Store-Newark | B14: 33741.2
A15: DC-PA | B15: 29348.23
A16: Store-Bronx | B16: 28505.45
A17: Store-Manhattan | B17: 26507.09
A18: Store-Yonkers | B18: 25794.9
A19: Store-WhitePlains | B19: 20949.6
A20: Store-Stamford | B20: 19133.26
A21: DC-NJ | B21: 14290.97
A24: Inventory Status Breakdown
A25: Status | B25: SKU Count | C25: Inventory Value
A26: Healthy | B26: 39 | C26: 82359.88
A27: Stockout Risk | B27: 21 | C27: 9173.15
A28: Excess | B28: 20 | C28: 69387.43
A29: Slow-Moving | B29: 5 | C29: 7107.71
A30: Excess / Aged | B30: 34 | C30: 149907.2
A31: Obsolete | B31: 1 | C31: 2215.4
A34: Aging Bucket Summary
A35: Aging Bucket | B35: SKU Count | C35: Inventory Value
A36: 0-90 Days | B36: 22 | C36: 54837.69
A37: 91-180 Days | B37: 19 | C37: 43764.88
A38: 181-365 Days | B38: 67 | C38: 190640.65
A39: 365+ Days | B39: 12 | C39: 30907.55
A42: Recommended Action Summary
A43: Recommended Action | B43: SKU Count | C43: Inventory Value
A44: Monitor | B44: 39 | C44: 82359.88
A45: Replenish | B45: 21 | C45: 9173.15
A46: Review Transfer | B46: 20 | C46: 69387.43
A47: Transfer or Markdown | B47: 34 | C47: 149907.2
A48: Markdown Review | B48: 5 | C48: 7107.71
...

Sheet Aged Excess Analysis
A1: Aged Excess Analysis — 81 Exception Items
A2: SKU | B2: Product Name | C2: Location | D2: Quantity On Hand | E2: Max Stock | F2: Excess Quantity | G2: Age Days | H2: 90 Day Demand | I2: Sell Through Rate | J2: Inventory Value | K2: Risk Level | L2: Issue Type | M2: Recommended Action | N2: Analyst Notes
A3: T-1019 | B3: Impact Wrench 1/2in 20V | C3: Store-Brooklyn | D3: 63 | E3: 36 | F3: 27 | G3: 212 | H3: 32 | I3: 0.3368 | J3: 12783.33 | K3: High | L3: Excess / Aged | M3: Transfer or Markdown | N3: Over max stock with extended age — evaluate transfer before markdown.
A4: T-1003 | B4: Mavis Fleet HD 225/75R16 | C4: Store-Bronx | D4: 85 | E4: 35 | F4: 50 | G4: 245 | H4: 6 | I4: 0.0659 | J4: 12643.75 | K4: High | L4: Excess / Aged | M4: Transfer or Markdown | N4: Over max stock with extended age — evaluate transfer before markdown.
A5: T-1023 | B5: Impact Wrench 1/2in 20V | C5: DC-PA | D5: 61 | E5: 41 | F5: 20 | G5: 245 | H5: 19 | I5: 0.2375 | J5: 12572.1 | K5: High | L5: Excess / Aged | M5: Transfer or Markdown | N5: Over max stock with extended age — evaluate transfer before markdown.
A6: B-1055 | B6: Deep Cycle Marine 27DC | C6: Store-Brooklyn | D6: 79 | E6: 60 | F6: 19 | G6: 197 | H6: 27 | I6: 0.2547 | J6: 11654.87 | K6: High | L6: Excess / Aged | M6: Transfer or Markdown | N6: Over max stock with extended age — evaluate transfer before markdown.
A7: B-1045 | B7: Deep Cycle Marine 27DC | C7: Store-Brooklyn | D7: 79 | E7: 50 | F7: 29 | G7: 365 | H7: 26 | I7: 0.2476 | J7: 11394.17 | K7: High | L7: Excess / Aged | M7: Transfer or Markdown | N7: Over max stock with extended age — evaluate transfer before markdown.
A8: B-1098 | B8: Mavis PowerStart 24F | C8: DC-PA | D8: 79 | E8: 58 | F8: 21 | G8: 269 | H8: 19 | I8: 0.1939 | J8: 9640.37 | K8: High | L8: Excess / Aged | M8: Transfer or Markdown | N8: Over max stock with extended age — evaluate transfer before markdown.
A9: T-1037 | B9: Hydraulic Floor Jack 3-Ton | C9: DC-NJ | D9: 56 | E9: 44 | F9: 12 | G9: 367 | H9: 1 | I9: 0.0175 | J9: 9064.72 | K9: High | L9: Excess / Aged | M9: Transfer or Markdown | N9: Over max stock with extended age — evaluate transfer before markdown.
A10: B-1030 | B10: Mavis AGM 47H6 | C10: Store-Manhattan | D10: 43 | E10: 30 | F10: 13 | G10: 283 | H10: 4 | I10: 0.0851 | J10: 8256.43 | K10: High | L10: Excess / Aged | M10: Transfer or Markdown | N10: Over max stock with extended age — evaluate transfer before markdown.
A11: B-1054 | B11: Deep Cycle Marine 27DC | C11: Store-Yonkers | D11: 55 | E11: 53 | F11: 2 | G11: 271 | H11: 21 | I11: 0.2763 | J11: 7709.9 | K11: High | L11: Excess / Aged | M11: Transfer or Markdown | N11: Over max stock with extended age — evaluate transfer before markdown.
A12: T-1072 | B12: Mavis Sport Grip 245/40R18 | C12: Store-Newark | D12: 57 | E12: 39 | F12: 18 | G12: 352 | H12: 1 | I12: 0.0172 | J12: 7450.47 | K12: High | L12: Excess / Aged | M12: Transfer or Markdown | N12: Over max stock with extended age — evaluate transfer before markdown.
A13: B-1087 | B13: Deep Cycle Marine 27DC | C13: Store-Manhattan | D13: 38 | E13: 37 | F13: 1 | G13: 264 | H13: 18 | I13: 0.3214 | J13: 5536.22 | K13: High | L13: Excess / Aged | M13: Transfer or Markdown | N13: Over max stock with extended age — evaluate transfer before markdown.
A14: B-1071 | B14: Deep Cycle Marine 27DC | C14: Store-Queens | D14: 34 | E14: 32 | F14: 2 | G14: 386 | H14: 25 | I14: 0.4237 | J14: 4754.22 | K14: High | L14: Excess / Aged | M14: Transfer or Markdown | N14: Over max stock with extended age — evaluate transfer before markdown.
... A83: F-1049 | B83: DOT 4 Brake Fluid 12oz | C83: DC-NJ | D83: 35 | E83: 31 | F83: 4 | G83: 13 | H83: 24 | I83: 0.4068 | J83: 211.75 | K83: Medium | L83: Excess | M83: Review Transfer | N83: Quantity exceeds max stock — consider transfer to locations with shortages.

Sheet Markdown Planner
A1: Markdown Planner — 60 Candidate Items
A2: SKU | B2: Product Name | C2: Location | D2: Quantity On Hand | E2: Unit Cost | F2: Current Selling Price | G2: Current Margin % | H2: Age Days | I2: Demand Trend | J2: Suggested Markdown % | K2: Markdown Price | L2: Projected Sell Through % | M2: Estimated Recovery Value | N2: Margin Impact | O2: Recommended Disposition
A3: T-1002 | B3: Mavis SnowTrack 205/55R16 | C3: DC-PA | D3: 22 | E3: 100.7 | F3: 138.79 | G3: 0.2744 | H3: 410 | I3: No Demand | J3: 0.3 | K3: 97.15 | L3: 0.135 | M3: 288.54 | N3: -10.54 | O3: Liquidate
A4: B-1045 | B4: Deep Cycle Marine 27DC | C4: Store-Brooklyn | D4: 79 | E4: 144.23 | F4: 210.9 | G4: 0.3161 | H4: 365 | I4: Moderate | J4: 0.2 | K4: 168.72 | L4: 0.3376 | M4: 4499.83 | N4: -650.93 | O4: 20% Markdown
A5: B-1054 | B5: Deep Cycle Marine 27DC | C5: Store-Yonkers | D5: 55 | E5: 140.18 | F5: 211.79 | G5: 0.3381 | H5: 271 | I5: Moderate | J5: 0.2 | K5: 169.43 | L5: 0.3663 | M5: 3413.42 | N5: -498.94 | O5: 20% Markdown
A6: B-1071 | B6: Deep Cycle Marine 27DC | C6: Store-Queens | D6: 34 | E6: 139.83 | F6: 230.6 | G6: 0.3936 | H6: 386 | I6: Moderate | J6: 0.2 | K6: 184.48 | L6: 0.5137 | M6: 3222.09 | N6: -527.77 | O6: 20% Markdown
A7: B-1030 | B7: Mavis AGM 47H6 | C7: Store-Manhattan | D7: 43 | E7: 192.01 | F7: 301.09 | G7: 0.3623 | H7: 283 | I7: Declining | J7: 0.2 | K7: 240.87 | L7: 0.1751 | M7: 1813.58 | N7: -31.27 | O7: 20% Markdown
A8: BP-1075 | B8: Vented Brake Rotor 11.8in | C8: DC-NY | D8: 84 | E8: 50.61 | F8: 69.19 | G8: 0.2685 | H8: 337 | I8: Moderate | J8: 0.2 | K8: 55.35 | L8: 0.3721 | M8: 1730.04 | N8: -292.12 | O8: 20% Markdown
A9: T-1037 | B9: Hydraulic Floor Jack 3-Ton | C9: DC-NJ | D9: 56 | E9: 161.87 | F9: 256.28 | G9: 0.3684 | H9: 367 | I9: Declining | J9: 0.2 | K9: 205.02 | L9: 0.1075 | M9: 1234.22 | N9: 167.24 | O9: 20% Markdown
A10: T-1072 | B10: Mavis Sport Grip 245/40R18 | C10: Store-Newark | D10: 57 | E10: 130.71 | F10: 202.56 | G10: 0.3547 | H10: 352 | I10: Declining | J10: 0.2 | K10: 162.05 | L10: 0.1072 | M10: 990.19 | N10: 121.06 | O10: 20% Markdown
A11: A-1031 | B11: LED Headlight Bulb H11 Pair | C11: Store-Yonkers | D11: 39 | E11: 37.2 | F11: 56.41 | G11: 0.3405 | H11: 385 | I11: Moderate | J11: 0.2 | K11: 45.13 | L11: 0.5558 | M11: 978.25 | N11: -177.08 | O11: 20% Markdown
A12: BP-1073 | B12: Ceramic Brake Pad Set - Front | C12: Store-WhitePlains | D12: 46 | E12: 33.36 | F12: 46.47 | G12: 0.2821 | H12: 377 | I12: Moderate | J12: 0.2 | K12: 37.18 | L12: 0.4847 | M12: 828.97 | N12: -152.86 | O12: 20% Markdown
A13: F-1105 | B13: Synthetic Motor Oil 5W-30 5qt | C13: Store-WhitePlains | D13: 55 | E13: 27.87 | F13: 43.75 | G13: 0.363 | H13: 329 | I13: Moderate | J13: 0.2 | K13: 35 | L13: 0.3154 | M13: 607.14 | N13: -73.18 | O13: 20% Markdown
A14: SS-1013 | B14: Nitrile Gloves Box/100 | C14: DC-NY | D14: 71 | E14: 19.28 | F14: 28.68 | G14: 0.3278 | H14: 280 | I14: Slow | J14: 0.2 | K14: 22.94 | L14: 0.2739 | M14: 446.11 | N14: -51.56 | O14: 20% Markdown
... A62: SS-1107 | B62: Assorted Clip & Retainer Kit | C62: Store-Yonkers | D62: 58 | E62: 21.37 | F62: 33.83 | G62: 0.3683 | H62: 148 | I62: No Demand | J62: 0 | K62: 33.83 | L62: 0 | M62: 0 | N62: 0 | O62: Transfer First

Sheet Transfer Planner
A1: Transfer Planner — 107 Recommended Transfers
A2: SKU | B2: Product Name | C2: Source Location | D2: Destination Location | E2: Source Quantity | F2: Destination Quantity | G2: Destination Min Stock | H2: Destination Demand | I2: Suggested Transfer Quantity | J2: Unit Cost | K2: Transfer Cost | L2: Estimated Margin Protected | M2: Net Benefit | N2: Recommendation
A3: T-1023 | B3: Impact Wrench 1/2in 20V | C3: DC-PA | D3: Store-Brooklyn | E3: 61 | F3: 63 | G3: 17 | H3: 32 | I3: 13 | J3: 206.1 | K3: 84.5 | L3: 937.75 | M3: 853.25 | N3: Transfer Recommended
A4: T-1096 | B4: Mavis Sport Grip 245/40R18 | C4: Store-Queens | D4: Store-WhitePlains | E4: 71 | F4: 6 | G4: 15 | H4: 25 | I4: 20 | J4: 129.57 | K4: 105 | L4: 906.99 | M4: 801.99 | N4: Transfer Recommended
A5: T-1023 | B5: Impact Wrench 1/2in 20V | C5: DC-PA | D5: Store-Queens | E5: 61 | F5: 10 | G5: 13 | H5: 19 | I5: 12 | J5: 206.1 | K5: 82 | L5: 865.62 | M5: 783.62 | N5: Transfer Recommended
A6: T-1019 | B6: Impact Wrench 1/2in 20V | C6: Store-Brooklyn | D6: Store-Queens | E6: 63 | F6: 10 | G6: 13 | H6: 19 | I6: 12 | J6: 202.91 | K6: 74.2 | L6: 852.22 | M6: 778.02 | N6: Transfer Recommended
A7: T-1072 | B7: Mavis Sport Grip 245/40R18 | C7: Store-Newark | D7: Store-WhitePlains | E7: 57 | F7: 6 | G7: 15 | H7: 25 | I7: 18 | J7: 130.71 | K7: 97.3 | L7: 823.47 | M7: 726.17 | N7: Transfer Recommended
A8: T-1072 | B8: Mavis Sport Grip 245/40R18 | C8: Store-Newark | D8: DC-NJ | E8: 57 | F8: 3 | G8: 12 | H8: 18 | I8: 18 | J8: 130.71 | K8: 101.1 | L8: 823.47 | M8: 722.37 | N8: Transfer Recommended
A9: T-1096 | B9: Mavis Sport Grip 245/40R18 | C9: Store-Queens | D9: DC-NJ | E9: 71 | F9: 3 | G9: 12 | H9: 18 | I9: 18 | J9: 129.57 | K9: 101.1 | L9: 816.29 | M9: 715.19 | N9: Transfer Recommended
A10: T-1023 | B10: Impact Wrench 1/2in 20V | C10: DC-PA | D10: Store-Bronx | E10: 61 | F10: 38 | G10: 8 | H10: 23 | I10: 10 | J10: 206.1 | K10: 77 | L10: 721.35 | M10: 644.35 | N10: Transfer Recommended
A11: T-1019 | B11: Impact Wrench 1/2in 20V | C11: Store-Brooklyn | D11: Store-Bronx | E11: 63 | F11: 38 | G11: 8 | H11: 23 | I11: 10 | J11: 202.91 | K11: 66.5 | L11: 710.18 | M11: 643.68 | N11: Transfer Recommended
A12: T-1037 | B12: Hydraulic Floor Jack 3-Ton | C12: DC-NJ | D12: DC-NY | E12: 56 | F12: 60 | G12: 14 | H12: 32 | I12: 12 | J12: 161.87 | K12: 66.4 | L12: 679.85 | M12: 613.45 | N12: Transfer Recommended
A13: B-1055 | B13: Deep Cycle Marine 27DC | C13: Store-Brooklyn | D13: Store-Stamford | E13: 79 | F13: 34 | G13: 14 | H13: 32 | I13: 13 | J13: 147.53 | K13: 78.05 | L13: 671.26 | M13: 593.21 | N13: Transfer Recommended
A14: B-1045 | B14: Deep Cycle Marine 27DC | C14: Store-Brooklyn | D14: Store-Stamford | E14: 79 | F14: 34 | G14: 14 | H14: 32 | I14: 13 | J14: 144.23 | K14: 78.05 | L14: 656.25 | M14: 578.2 | N14: Transfer Recommended
... A109: SS-1084 | B109: Nitrile Gloves Box/100 | C109: Store-Manhattan | D109: Store-Newark | E109: 79 | F109: 32 | G109: 14 | H109: 31 | I109: 12 | J109: 18.22 | K109: 74.2 | L109: 76.52 | M109: 2.32 | N109: Review Transfer

Sheet IT Asset Register
A1: IT Asset Register — 120 Assets Under Management
A2: Asset Tag | B2: Serial Number | C2: Device Type | D2: Make | E2: Model | F2: Assigned User | G2: Department | H2: Location | I2: Borough | J2: Purchase Date | K2: Warranty Expiration | L2: Status | M2: Condition | N2: Last Audit Date | O2: Lifecycle Stage | P2: Notes
A3: LAP-00001 | B3: LEN64480620 | C3: Laptop | D3: Lenovo | E3: ThinkPad T14 | F3: Maria Gonzalez | G3: Store Operations | H3: DC-NJ | I3: Newark | J3: 45916 | K3: 47011 | L3: Assigned | M3: Good | N3: 46110 | O3: Assigned | P3: Primary workstation — annual audit current.
A4: LAP-00002 | B4: HP77775184 | C4: Laptop | D4: HP | E4: EliteBook 840 G10 | G4: Warehouse | H4: DC-PA | I4: Allentown | J4: 45382 | K4: 46477 | L4: In Stock | M4: Excellent | N4: 46087 | O4: In Stock | P4: Spare pool device — ready for deployment.
A5: DSK-00003 | B5: DEL19764854 | C5: Desktop | D5: Dell | E5: OptiPlex 7010 | F5: James Rivera | G5: Finance | H5: Store-Bronx | I5: Bronx | J5: 45414 | K5: 46509 | L5: Missing | M5: Unknown | N5: 46157 | O5: Assigned | P5: Not located during Q2 physical audit — follow-up open.
A6: DSK-00004 | B6: HP05808826 | C6: Desktop | D6: HP | E6: ProDesk 400 G9 | G6: HR | H6: Store-Queens | I6: Queens | J6: 45475 | K6: 46570 | L6: Retired | M6: Fair | N6: 46173 | O6: Retired | P6: End of life — removed from active inventory.
A7: PRT-00005 | B7: HP73094867 | C7: Printer | D7: HP | E7: LaserJet Pro M404dn | F7: Former Employee | G7: Procurement | H7: Store-Brooklyn | I7: Brooklyn | J7: 45823 | K7: 46188 | L7: Returned | M7: Poor | N7: 46112 | O7: Retired | P7: Pending disposal — awaiting data wipe and vendor pickup.
A8: PRT-00006 | B8: CAN34405176 | C8: Printer | D8: Canon | E8: imageCLASS MF455dw | F8: Carlos Mendez | G8: Customer Service | H8: Store-Manhattan | I8: Manhattan | J8: 45097 | K8: 45462 | L8: In Repair | M8: Damaged | N8: 46177 | O8: In Repair | P8: Keyboard replacement — vendor RMA in progress.
A9: SCN-00007 | B9: FUJ39439304 | C9: Scanner | D9: Fujitsu | E9: fi-7160 | G9: Field Support | H9: Store-WhitePlains | I9: Westchester | J9: 44899 | K9: 45264 | L9: Disposed | M9: Poor | N9: 46114 | O9: Disposed | P9: Disposed per certificate IT-DSP-2025-0142.
A10: MON-00008 | B10: LG56941867 | C10: Monitor | D10: LG | E10: 27BN85U-N | F10: Allison Hill | G10: Finance | H10: DC-PA | I10: Allentown | J10: 45889 | K10: 46254 | L10: Assigned | M10: Good | N10: 46173 | O10: Assigned
A11: LAP-00009 | B11: LEN82266181 | C11: Laptop | D11: Lenovo | E11: ThinkPad T14 | F11: Noah Rhodes | G11: Customer Service | H11: Store-Bronx | I11: Bronx | J11: 44671 | K11: 45766 | L11: In Repair | M11: Damaged | N11: 46155 | O11: In Repair | P11: Auto-generated record — status In Repair.
A12: MON-00010 | B12: LG27545501 | C12: Monitor | D12: LG | E12: 27BN85U-N | G12: Customer Service | H12: DC-NY | I12: Queens | J12: 44749 | K12: 45114 | L12: In Stock | M12: Fair | N12: 46118 | O12: In Stock | P12: Auto-generated record — status In Stock.
A13: DSK-00011 | B13: DEL07565505 | C13: Desktop | D13: Dell | E13: OptiPlex 7010 | F13: Angie Henderson | G13: Finance | H13: DC-NJ | I13: Newark | J13: 44955 | K13: 46050 | L13: Assigned | M13: Damaged | N13: 46134 | O13: Assigned
A14: MON-00012 | B14: LG24980280 | C14: Monitor | D14: LG | E14: 27BN85U-N | F14: Daniel Wagner | G14: HR | H14: Store-Bronx | I14: Bronx | J14: 46061 | K14: 46426 | L14: Assigned | M14: Damaged | N14: 46175 | O14: Assigned
A15: MON-00013 | B15: LG57964448 | C15: Monitor | D15: LG | E15: 27BN85U-N | G15: Field Support | H15: Store-Bronx | I15: Bronx | J15: 45605 | K15: 45970 | L15: In Stock | M15: Excellent | N15: 46135 | O15: In Stock | P15: Auto-generated record — status In Stock.
A16: DSK-00014 | B16: HP64719591 | C16: Desktop | D16: HP | E16: ProDesk 400 G9 | F16: Cristian Santos | G16: Warehouse | H16: DC-PA | I16: Allentown | J16: 46075 | K16: 47170 | L16: Assigned | M16: Poor | N16: 46116 | O16: Assigned
A17: PRT-00015 | B17: CAN66639031 | C17: Printer | D17: Canon | E17: imageCLASS MF455dw | F17: Connie Lawrence | G17: Finance | H17: Store-Yonkers | I17: Westchester | J17: 45340 | K17: 45705 | L17: Assigned | M17: Good | N17: 46165 | O17: Assigned
A18: DSK-00016 | B18: HP79272774 | C18: Desktop | D18: HP | E18: ProDesk 400 G9 | G18: Warehouse | H18: HQ-Queens | I18: Queens | J18: 44538 | K18: 45633 | L18: In Stock | M18: Fair | N18: 46169 | O18: In Stock | P18: Auto-generated record — status In Stock.
A19: MON-00017 | B19: DEL72738551 | C19: Monitor | D19: Dell | E19: UltraSharp U2723QE | G19: IT | H19: Store-Bronx | I19: Bronx | J19: 45947 | K19: 46312 | L19: Retired | M19: Excellent | N19: 46147 | O19: Retired | P19: Auto-generated record — status Retired.
A20: PRT-00018 | B20: CAN36150660 | C20: Printer | D20: Canon | E20: imageCLASS MF455dw | G20: IT | H20: Store-Stamford | I20: Stamford | J20: 44798 | K20: 45163 | L20: In Stock | M20: Poor | N20: 46150 | O20: In Stock | P20: Auto-generated record — status In Stock.
A21: MON-00019 | B21: DEL61611571 | C21: Monitor | D21: Dell | E21: UltraSharp U2723QE | F21: Abigail Shaffer | G21: Customer Service | H21: Store-Queens | I21: Queens | J21: 46042 | K21: 46407 | L21: Assigned | M21: Excellent | N21: 46162 | O21: Assigned
A22: DSK-00020 | B22: HP20194447 | C22: Desktop | D22: HP | E22: ProDesk 400 G9 | F22: Gina Moore | G22: Field Support | H22: HQ-Queens | I22: Queens | J22: 45106 | K22: 46201 | L22: Assigned | M22: Poor | N22: 46132 | O22: Assigned
A23: LAP-00021 | B23: DEL15548293 | C23: Laptop | D23: Dell | E23: Latitude 5540 | F23: Gabrielle Davis | G23: Warehouse | H23: DC-NY | I23: Queens | J23: 45270 | K23: 46365 | L23: Assigned | M23: Fair | N23: 46092 | O23: Assigned
A24: SCN-00022 | B24: FUJ08513531 | C24: Scanner | D24: Fujitsu | E24: fi-7160 | F24: Ryan Munoz | G24: Customer Service | H24: Store-Manhattan | I24: Manhattan | J24: 45353 | K24: 45718 | L24: Assigned | M24: Good | N24: 46104 | O24: Assigned
A25: MOB-00023 | B25: SAM97316992 | C25: Mobile Phone | D25: Samsung | E25: Galaxy S24 | G25: IT | H25: Store-Yonkers | I25: Westchester | J25: 45627 | K25: 46722 | L25: In Stock | M25: Poor | N25: 46116 | O25: In Stock | P25: Auto-generated record — status In Stock.
A26: DSK-00024 | B26: DEL48932962 | C26: Desktop | D26: Dell | E26: OptiPlex 7010 | F26: Monica Herrera | G26: Store Operations | H26: DC-NY | I26: Queens | J26: 45152 | K26: 46247 | L26: Assigned | M26: Good | N26: 46104 | O26: Assigned
A27: MOB-00025 | B27: APP50249918 | C27: Mobile Phone | D27: Apple | E27: iPhone 15 | F27: Jamie Arnold | G27: Field Support | H27: Store-Manhattan | I27: Manhattan | J27: 45670 | K27: 46765 | L27: Missing | M27: Excellent | N27: 46181 | O27: Assigned | P27: Auto-generated record — status Missing.
A28: LAP-00026 | B28: LEN43073643 | C28: Laptop | D28: Lenovo | E28: ThinkPad T14 | G28: Customer Service | H28: Store-Yonkers | I28: Westchester | J28: 44569 | K28: 45664 | L28: Retired | M28: Excellent | N28: 46140 | O28: Retired | P28: Auto-generated record — status Retired.
A29: NET-00027 | B29: CIS92010881 | C29: Network Device | D29: Cisco | E29: Meraki MR46 | F29: Lisa Hensley | G29: Procurement | H29: DC-NJ | I29: Newark | J29: 44819 | K29: 45184 | L29: Assigned | M29: Excellent | N29: 46092 | O29: Assigned
A30: MON-00028 | B30: DEL23973945 | C30: Monitor | D30: Dell | E30: UltraSharp U2723QE | G30: Warehouse | H30: DC-PA | I30: Allentown | J30: 45075 | K30: 45440 | L30: Retired | M30: Excellent | N30: 46177 | O30: Retired | P30: Auto-generated record — status Retired.
A31: PRT-00029 | B31: CAN06912596 | C31: Printer | D31: Canon | E31: imageCLASS MF455dw | F31: Michele Williams | G31: Field Support | H31: DC-NJ | I31: Newark | J31: 46090 | K31: 46455 | L31: Assigned | M31: Good | N31: 46184 | O31: Assigned
A32: MON-00030 | B32: DEL07814159 | C32: Monitor | D32: Dell | E32: UltraSharp U2723QE | F32: Dylan Miller | G32: Finance | H32: Store-Manhattan | I32: Manhattan | J32: 45768 | K32: 46133 | L32: In Repair | M32: Excellent | N32: 46117 | O32: In Repair | P32: Auto-generated record — status In Repair.
A33: LAP-00031 | B33: LEN39529940 | C33: Laptop | D33: Lenovo | E33: ThinkPad T14 | F33: Brian Ramirez | G33: Field Support | H33: Store-Queens | I33: Queens | J33: 45592 | K33: 46687 | L33: Assigned | M33: Fair | N33: 46123 | O33: Assigned
A34: MOB-00032 | B34: APP74091519 | C34: Mobile Phone | D34: Apple | E34: iPhone 15 | F34: Holly Wood | G34: Store Operations | H34: Store-Manhattan | I34: Manhattan | J34: 45015 | K34: 46110 | L34: Assigned | M34: Poor | N34: 46183 | O34: Assigned
A35: MON-00033 | B35: DEL61282742 | C35: Monitor | D35: Dell | E35: UltraSharp U2723QE | F35: Derek Zuniga | G35: Finance | H35: Store-Newark | I35: Newark | J35: 45304 | K35: 45669 | L35: In Repair | M35: Damaged | N35: 46197 | O35: In Repair | P35: Auto-generated record — status In Repair.
A36: DSK-00034 | B36: HP24139416 | C36: Desktop | D36: HP | E36: ProDesk 400 G9 | G36: Customer Service | H36: Store-Manhattan | I36: Manhattan | J36: 45063 | K36: 46158 | L36: Retired | M36: Poor | N36: 46130 | O36: Retired | P36: Auto-generated record — status Retired.
A37: NET-00035 | B37: UBI97889180 | C37: Network Device | D37: Ubiquiti | E37: UniFi AP U6 Pro | F37: Lisa Jackson | G37: Warehouse | H37: Store-Stamford | I37: Stamford | J37: 45327 | K37: 45692 | L37: Assigned | M37: Good | N37: 46172 | O37: Assigned
A38: PRT-00036 | B38: CAN91995112 | C38: Printer | D38: Canon | E38: imageCLASS MF455dw | G38: Warehouse | H38: Store-WhitePlains | I38: Westchester | J38: 45861 | K38: 46226 | L38: Returned | M38: Good | N38: 46164 | O38: Returned | P38: Auto-generated record — status Returned.
A39: MOB-00037 | B39: APP11804556 | C39: Mobile Phone | D39: Apple | E39: iPhone 15 | F39: Carla Gray | G39: Finance | H39: DC-NJ | I39: Newark | J39: 45914 | K39: 47009 | L39: Assigned | M39: Poor | N39: 46193 | O39: Assigned
A40: MON-00038 | B40: LG78504182 | C40: Monitor | D40: LG | E40: 27BN85U-N | G40: Customer Service | H40: Store-Queens | I40: Queens | J40: 45563 | K40: 45928 | L40: In Stock | M40: Poor | N40: 46099 | O40: In Stock | P40: Auto-generated record — status In Stock.
...

Sheet Audit Reconciliation
A1: Audit Reconciliation
A3: Total Assets Audited | C3: Exception Count | E3: Exception Rate | G3: High Priority Exceptions | I3: Open Exceptions
A4: 118 | C4: 20 | E4: 0.16949153 | G4: 9 | I4: 13
A6: Exception Summary by Type
A7: Exception Type | B7: Count
A8: Missing from Audit | B8: 4
A9: Found Not in System | B9: 1
A10: Wrong Location | B10: 3
A11: Wrong User | B11: 4
A12: Duplicate Serial Number | B12: 1
A13: Missing Asset Tag | B13: 4
A14: Retired but Active | B14: 3
A15: No Exception | B15: 98
A17: System Inventory (Sample)
A18: Asset Tag | B18: Serial Number | C18: Device Type | D18: Location | E18: Assigned User | F18: Status
A19: LAP-00001 | B19: LEN64480620 | C19: Laptop | D19: DC-NJ | E19: Maria Gonzalez | F19: Assigned
A20: LAP-00002 | B20: HP77775184 | C20: Laptop | D20: DC-PA | E20: Unassigned | F20: In Stock
A21: DSK-00003 | B21: DEL19764854 | C21: Desktop | D21: Store-Bronx | E21: James Rivera | F21: Missing
A22: DSK-00004 | B22: HP05808826 | C22: Desktop | D22: Store-Queens | E22: Unassigned | F22: Retired
A23: PRT-00005 | B23: HP73094867 | C23: Printer | D23: Store-Brooklyn | E23: Former Employee | F23: Returned
A24: PRT-00006 | B24: CAN34405176 | C24: Printer | D24: Store-Manhattan | E24: Carlos Mendez | F24: In Repair
A25: MON-00008 | B25: LG56941867 | C25: Monitor | D25: DC-PA | E25: Allison Hill | F25: Assigned
A26: LAP-00009 | B26: LEN82266181 | C26: Laptop | D26: Store-Bronx | E26: Noah Rhodes | F26: In Repair
A27: MON-00010 | B27: LG27545501 | C27: Monitor | D27: DC-NY | E27: Unassigned | F27: In Stock
A28: DSK-00011 | B28: DEL07565505 | C28: Desktop | D28: DC-NJ | E28: Angie Henderson | F28: Assigned
A29: MON-00012 | B29: LG24980280 | C29: Monitor | D29: Store-Bronx | E29: Daniel Wagner | F29: Assigned
... A36: MON-00019 | B36: DEL61611571 | C36: Monitor | D36: Store-Queens | E36: Abigail Shaffer | F36: Assigned
A38: Physical Audit Count (Sample)
A39: Asset Tag | B39: Serial Number | C39: Location | D39: Assigned User | E39: Physical Status
A40: LAP-00001 | B40: LEN64480620 | C40: DC-NJ | D40: Maria Gonzalez | E40: Present
A41: LAP-00002 | B41: HP77775184 | C41: DC-PA | D41: Unassigned | E41: Present
A42: DSK-00003 | B42: DEL19764854 | C42: Store-Bronx | D42: James Rivera | E42: Not Found
A43: DSK-00004 | B43: HP05808826 | C43: Store-Queens | D43: Unassigned | E43: Present
A44: PRT-00005 | B44: HP73094867 | C44: Store-Brooklyn | D44: Former Employee | E44: Present
A45: PRT-00006 | B45: CAN34405176 | C45: Store-Manhattan | D45: Carlos Mendez | E45: Present
A46: MON-00008 | B46: LG56941867 | C46: DC-PA | D46: Allison Hill | E46: Present
A47: LAP-00009 | B47: LEN82266181 | C47: Store-Bronx | D47: Noah Rhodes | E47: Present
A48: MON-00010 | B48: LG27545501 | C48: DC-NY | D48: Unassigned | E48: Present
A49: DSK-00011 | B49: DEL07565505 | C49: DC-NJ | D49: Angie Henderson | E49: Present
A50: MON-00012 | B50: LG24980280 | C50: Store-Bronx | D50: Daniel Wagner | E50: Present
...

Sheet Software Licenses
A1: Software Licenses — 22 Applications Tracked
A2: License Portfolio Summary
A3: Total Software Records | C3: Over-Assigned Count | E3: Renewals Due ≤ 30 Days | G3: Renewals Due ≤ 90 Days | I3: Total Annual Cost
A4: 22 | C4: 1 | E4: 1 | G4: 6 | I4: 463776.77
A6: Software Name | B6: Vendor | C6: License Type | D6: Purchased Licenses | E6: Assigned Licenses | F6: Available Licenses | G6: Renewal Date | H6: Days Until Renewal | I6: Department | J6: Owner | K6: Annual Cost | L6: Compliance Status
A7: Adobe Creative Cloud | B7: Adobe | C7: Subscription | D7: 50 | E7: 58 | F7: -8 | G7: 46324 | H7: 120 | I7: Finance | J7: Allison Hill | K7: 13361.06 | L7: Over-Assigned
A8: Zoom Business | B8: Zoom | C8: Subscription | D8: 200 | E8: 185 | F8: 15 | G8: 46226 | H8: 22 | I8: HR | J8: Noah Rhodes | K8: 6139.37 | L8: Renewal Due Soon
A9: Slack Enterprise Grid | B9: Salesforce | C9: Subscription | D9: 75 | E9: 70 | F9: 5 | G9: 46264 | H9: 60 | I9: Store Operations | J9: Angie Henderson | K9: 19561.45 | L9: Renewal Watch
A10: ServiceNow ITSM | B10: ServiceNow | C10: Subscription | D10: 120 | E10: 115 | F10: 5 | G10: 46294 | H10: 90 | I10: Warehouse | J10: Daniel Wagner | K10: 94905.26 | L10: Renewal Watch
A11: CrowdStrike Falcon | B11: CrowdStrike | C11: Subscription | D11: 300 | E11: 245 | F11: 55 | G11: 46404 | H11: 200 | I11: Procurement | J11: Cristian Santos | K11: 31792.32 | L11: Compliant
A12: AutoCAD LT | B12: Autodesk | C12: Perpetual + Maintenance | D12: 300 | E12: 234 | F12: 66 | G12: 46470 | H12: 266 | I12: Procurement | J12: Connie Lawrence | K12: 8370.43 | L12: Compliant
A13: Confluence | B13: Atlassian | C13: Subscription | D13: 193 | E13: 104 | F13: 89 | G13: 46348 | H13: 144 | I13: Procurement | J13: Abigail Shaffer | K13: 5768.72 | L13: Compliant
A14: Confluence | B14: Atlassian | C14: Subscription | D14: 175 | E14: 149 | F14: 26 | G14: 46409 | H14: 205 | I14: Store Operations | J14: Gina Moore | K14: 5164.33 | L14: Compliant
A15: Okta SSO | B15: Okta | C15: Subscription | D15: 232 | E15: 211 | F15: 21 | G15: 46241 | H15: 37 | I15: IT | J15: Gabrielle Davis | K15: 16417.77 | L15: Renewal Watch
A16: ServiceNow ITSM | B16: ServiceNow | C16: Subscription | D16: 86 | E16: 71 | F16: 15 | G16: 46464 | H16: 260 | I16: Store Operations | J16: Ryan Munoz | K16: 98928.67 | L16: Compliant
A17: CrowdStrike Falcon | B17: CrowdStrike | C17: Subscription | D17: 359 | E17: 249 | F17: 110 | G17: 46491 | H17: 287 | I17: HR | J17: Monica Herrera | K17: 32338.83 | L17: Compliant
A18: CrowdStrike Falcon | B18: CrowdStrike | C18: Subscription | D18: 211 | E18: 19 | F18: 192 | G18: 46410 | H18: 206 | I18: HR | J18: Jamie Arnold | K18: 34995.79 | L18: Compliant
... A28: DocuSign Business Pro | B28: DocuSign | C28: Subscription | D28: 345 | E28: 202 | F28: 143 | G28: 46246 | H28: 42 | I28: HR | J28: Patty Perez | K28: 4903.46 | L28: Renewal Watch

Sheet Mobile Provisioning
A1: Mobile Provisioning — 45 Devices Tracked
A2: Provisioning Checklist Summary
A3: Total Mobile Devices | D3: Assigned Devices | G3: Pending Setup | J3: Missing User Agreement | M3: Returned Devices
A4: 45 | D4: 9 | G4: 7 | J4: 8 | M4: 5
A6: Employee Name | B6: Department | C6: Device Type | D6: Asset Tag | E6: IMEI | F6: SIM Number | G6: Phone Number | H6: Carrier | I6: MDM Enrolled | J6: Security Configured | K6: Required Apps Installed | L6: User Agreement Signed | M6: Date Issued | N6: Return Date | O6: Status
A7: Michael Thomas | B7: Warehouse | C7: iPhone 14 | D7: MOB-00001 | E7: 640502845928732 | F7: 89012464193812728440 | G7: (537) 446-5930 | H7: T-Mobile | I7: No | J7: No | K7: No | L7: No | M7: 46197 | O7: Pending Setup
A8: Michael Mcguire | B8: IT | C8: Samsung Galaxy S24 | D8: MOB-00002 | E8: 835448995799900 | F8: 89015187111383756064 | G8: (311) 643-6485 | H8: Verizon | I8: Yes | J8: Yes | K8: Yes | L8: Yes | M8: 46167 | O8: Assigned
A9: Jonathan Smith | B9: Field Support | C9: Samsung Galaxy A54 | D9: MOB-00003 | E9: 375035424306550 | F9: 89016580351822301324 | G9: (711) 689-8825 | H9: Verizon | I9: Yes | J9: Yes | K9: Yes | L9: No | M9: 45919 | O9: Missing Agreement
A10: Jaime Phelps | B10: Finance | C10: iPhone 15 | D10: MOB-00004 | E10: 600834856867184 | F10: 89013111023967588886 | G10: (596) 336-2104 | H10: T-Mobile | I10: Yes | J10: Yes | K10: Yes | L10: Yes | O10: Ready
A11: Nicole Hamilton | B11: HR | C11: iPhone 14 | D11: MOB-00005 | E11: 908264648964614 | F11: 89017394882698457556 | G11: (988) 754-5532 | H11: Verizon | I11: No | J11: No | K11: No | L11: Yes | M11: 45761 | N11: 46172 | O11: Returned
A12: Samuel Wilkins | B12: Customer Service | C12: Samsung Galaxy A54 | D12: MOB-00006 | E12: 265267579339797 | F12: 89012573272978994337 | G12: (425) 760-5083 | H12: Verizon | I12: Yes | J12: Yes | K12: Yes | L12: Yes | M12: 45668 | O12: Assigned
A13: Brendan Hunt | B13: Warehouse | C13: Samsung Galaxy A54 | D13: MOB-00007 | E13: 758775409569406 | F13: 89011765441925059959 | G13: (250) 720-8121 | H13: AT&T | I13: Yes | J13: Yes | K13: Yes | L13: No | M13: 46029 | O13: Missing Agreement
A14: Raymond Harper MD | B14: Warehouse | C14: iPhone 14 | D14: MOB-00008 | E14: 832008329114061 | F14: 89010814996896238918 | G14: (696) 427-8237 | H14: Verizon | I14: Yes | J14: Yes | K14: Yes | L14: No | M14: 46124 | O14: Missing Agreement
A15: Jamie Williams | B15: Customer Service | C15: Samsung Galaxy S24 | D15: MOB-00009 | E15: 876883919037228 | F15: 89019328721104932079 | G15: (331) 459-3834 | H15: Verizon | I15: Yes | J15: Yes | K15: Yes | L15: Yes | M15: 45777 | O15: Assigned
A16: Tom Combs | B16: Warehouse | C16: iPhone 15 | D16: MOB-00010 | E16: 979460348121415 | F16: 89012539539357889157 | G16: (281) 783-1440 | H16: T-Mobile | I16: Yes | J16: Yes | K16: Yes | L16: Yes | M16: 45971 | O16: Assigned
A17: Stephen Boyd | B17: HR | C17: Samsung Galaxy S24 | D17: MOB-00011 | E17: 467108837254665 | F17: 89017404101679242106 | G17: (720) 553-3324 | H17: Verizon | I17: No | J17: No | K17: No | L17: Yes | M17: 46199 | O17: Disabled
A18: Scott Silva | B18: Field Support | C18: Samsung Galaxy S24 | D18: MOB-00012 | E18: 880437810028342 | F18: 89017903239314522333 | G18: (239) 914-7121 | H18: T-Mobile | I18: No | J18: No | K18: No | L18: Yes | M18: 46202 | O18: Disabled
A19: Meghan Davis | B19: Finance | C19: iPhone 14 | D19: MOB-00013 | E19: 888380720003650 | F19: 89013353532285422652 | G19: (670) 537-6403 | H19: AT&T | I19: Yes | J19: Yes | K19: No | L19: Yes | O19: Ready
A20: Rachel Nolan | B20: Field Support | C20: Samsung Galaxy A54 | D20: MOB-00014 | E20: 498671821496299 | F20: 89012677943176194122 | G20: (501) 513-3581 | H20: T-Mobile | I20: No | J20: No | K20: No | L20: Yes | M20: 46083 | N20: 46129 | O20: Returned
A21: Joseph Haynes | B21: Finance | C21: Samsung Galaxy S24 | D21: MOB-00015 | E21: 030363621798015 | F21: 89010508064574334286 | G21: (932) 384-1764 | H21: T-Mobile | I21: No | J21: No | K21: No | L21: Yes | M21: 45768 | N21: 46158 | O21: Returned
A22: Ryan Norman | B22: Finance | C22: iPhone 14 | D22: MOB-00016 | E22: 517670590893390 | F22: 89016675265711198712 | G22: (333) 660-2270 | H22: T-Mobile | I22: No | J22: Yes | K22: No | L22: Yes | M22: 46080 | O22: Assigned
A23: Kevin Richardson | B23: Field Support | C23: iPhone 14 | D23: MOB-00017 | E23: 970814065524123 | F23: 89014242200359569258 | G23: (509) 416-1019 | H23: AT&T | I23: No | J23: No | K23: No | L23: No | M23: 46194 | O23: Pending Setup
A24: Larry Costa | B24: Customer Service | C24: iPhone 15 | D24: MOB-00018 | E24: 654643257787213 | F24: 89017492073680271998 | G24: (757) 567-4347 | H24: Verizon | I24: Yes | J24: Yes | K24: Yes | L24: Yes | O24: Ready
A25: Ashley Simpson | B25: Store Operations | C25: Samsung Galaxy A54 | D25: MOB-00019 | E25: 578752502762027 | F25: 89010871631270137497 | G25: (855) 841-9646 | H25: AT&T | I25: No | J25: No | K25: No | L25: Yes | M25: 46195 | O25: Disabled
A26: Tina Espinoza | B26: Warehouse | C26: Samsung Galaxy A54 | D26: MOB-00020 | E26: 106793298293986 | F26: 89012689099387498196 | G26: (889) 959-2765 | H26: T-Mobile | I26: Yes | J26: Yes | K26: Yes | L26: No | M26: 45794 | O26: Missing Agreement
A27: Vincent Guzman | B27: Store Operations | C27: iPhone 14 | D27: MOB-00021 | E27: 169838007320037 | F27: 89011818752931694628 | G27: (316) 752-1475 | H27: Verizon | I27: Yes | J27: No | K27: Yes | L27: Yes | O27: Ready
A28: Cameron Miller | B28: Procurement | C28: iPhone 14 | D28: MOB-00022 | E28: 545574982909537 | F28: 89013462157714897525 | G28: (792) 269-2004 | H28: AT&T | I28: No | J28: No | K28: No | L28: Yes | M28: 46198 | O28: Disabled
A29: Brittany Aguirre | B29: Store Operations | C29: iPhone 15 | D29: MOB-00023 | E29: 283804222287406 | F29: 89016343987233611008 | G29: (805) 448-6491 | H29: T-Mobile | I29: No | J29: No | K29: No | L29: Yes | M29: 46203 | O29: Disabled
A30: Joseph Ramos | B30: Field Support | C30: Samsung Galaxy S24 | D30: MOB-00024 | E30: 832043152921538 | F30: 89010043907044926854 | G30: (371) 437-6988 | H30: AT&T | I30: No | J30: No | K30: No | L30: No | M30: 46201 | O30: Pending Setup
A31: Aaron Berger | B31: IT | C31: iPhone 14 | D31: MOB-00025 | E31: 558167145732547 | F31: 89011461155462468799 | G31: (810) 994-2438 | H31: Verizon | I31: Yes | J31: Yes | K31: Yes | L31: Yes | M31: 45962 | O31: Assigned
A32: Becky Navarro | B32: IT | C32: Samsung Galaxy S24 | D32: MOB-00026 | E32: 692774703887714 | F32: 89011745324870342919 | G32: (624) 409-3523 | H32: AT&T | I32: Yes | J32: Yes | K32: Yes | L32: No | O32: Ready
A33: Stephanie Dyer MD | B33: IT | C33: iPhone 15 | D33: MOB-00027 | E33: 894825270822773 | F33: 89015500007239836696 | G33: (636) 902-9554 | H33: Verizon | I33: Yes | J33: Yes | K33: Yes | L33: Yes | O33: Ready
A34: Kathleen Pineda | B34: Procurement | C34: Samsung Galaxy S24 | D34: MOB-00028 | E34: 216427112098539 | F34: 89012821926594718400 | G34: (289) 548-9106 | H34: AT&T | I34: Yes | J34: Yes | K34: Yes | L34: Yes | O34: Ready
A35: Sarah Vincent | B35: Procurement | C35: iPhone 15 | D35: MOB-00029 | E35: 425499687355166 | F35: 89015033565740156482 | G35: (338) 377-6683 | H35: T-Mobile | I35: No | J35: No | K35: No | L35: Yes | M35: 45905 | N35: 46165 | O35: Returned
A36: Michael Davis | B36: HR | C36: iPhone 14 | D36: MOB-00030 | E36: 692732587724482 | F36: 89011373843073879378 | G36: (470) 457-7609 | H36: T-Mobile | I36: No | J36: No | K36: No | L36: No | M36: 46191 | O36: Pending Setup
A37: Timothy Sullivan | B37: Procurement | C37: Samsung Galaxy S24 | D37: MOB-00031 | E37: 997891541686802 | F37: 89015343064779849238 | G37: (229) 894-7090 | H37: Verizon | I37: Yes | J37: No | K37: Yes | L37: Yes | M37: 46073 | O37: Assigned
A38: Laura Green | B38: Procurement | C38: iPhone 15 | D38: MOB-00032 | E38: 605844316339178 | F38: 89014089623756902396 | G38: (832) 863-7902 | H38: Verizon | I38: Yes | J38: Yes | K38: Yes | L38: No | M38: 46138 | O38: Missing Agreement
A39: Susan Murphy | B39: Customer Service | C39: Samsung Galaxy S24 | D39: MOB-00033 | E39: 071103582537701 | F39: 89011016788764254822 | G39: (836) 499-5308 | H39: T-Mobile | I39: No | J39: No | K39: No | L39: No | M39: 46199 | O39: Pending Setup
A40: Cody Thompson | B40: Customer Service | C40: iPhone 14 | D40: MOB-00034 | E40: 379175245319313 | F40: 89019031666616713741 | G40: (494) 264-8678 | H40: T-Mobile | I40: No | J40: No | K40: No | L40: Yes | M40: 46194 | O40: Disabled
A41: Michelle Hanna | B41: HR | C41: Samsung Galaxy S24 | D41: MOB-00035 | E41: 668384200602942 | F41: 89019535909435905463 | G41: (776) 982-1637 | H41: AT&T | I41: No | J41: No | K41: No | L41: No | M41: 46200 | O41: Pending Setup
...

Sheet Disposal Log
A1: Disposal Log — 25 Retirement Records
A2: Disposal Pipeline Summary
A3: Total Disposal Records | D3: Pending Wipe | G3: Certificate Missing | J3: Disposed | M3: Hold for Review
A4: 25 | D4: 11 | G4: 7 | J4: 3 | M4: 3
A6: Asset Tag | B6: Serial Number | C6: Device Type | D6: Assigned User | E6: Return Date | F6: Condition | G6: Data Wipe Required | H6: Data Wipe Completed | I6: Wipe Method | J6: Disposal Vendor | K6: Certificate Received | L6: Disposal Date | M6: Approved By | N6: Disposal Status
A7: DSP-00001 | B7: SN18264095 | C7: Desktop | D7: Joshua Atkins | E7: 46121 | F7: Fair | G7: Yes | H7: No | K7: No | M7: Patricia Nguyen | N7: Pending Wipe
A8: DSP-00002 | B8: SN98011346 | C8: Mobile Phone | D8: Danny Johnson | E8: 46177 | F8: Poor | G8: Yes | H8: Yes | I8: NIST 800-88 Clear | J8: EcoCycle IT Disposal | K8: No | M8: Robert Kim | N8: Certificate Missing
A9: DSP-00003 | B9: SN49344999 | C9: Printer | D9: Adam Moore | E9: 46114 | F9: Damaged | G9: Yes | H9: Yes | I9: NIST 800-88 Clear | J9: SecureShred Electronics | K9: Yes | L9: 46186 | M9: Sandra Lopez | N9: Disposed
A10: DSP-00004 | B10: SN74057195 | C10: Monitor | D10: Virginia Steele | E10: 46130 | F10: Non-Functional | G10: No | H10: No | K10: No | M10: Daniel A. Cruz | N10: Hold for Review
A11: DSP-00005 | B11: SN81917860 | C11: Scanner | D11: Jared Vazquez | E11: 46137 | F11: Good | G11: Yes | H11: Yes | I11: DOD 5220.22-M | J11: Metro E-Waste Partners | K11: No | M11: Patricia Nguyen | N11: Pending Vendor Pickup
A12: DSP-00006 | B12: SN76231375 | C12: Desktop | D12: Benjamin Skinner | E12: 46075 | F12: Damaged | G12: Yes | H12: Yes | K12: Yes | L12: 46146 | M12: Patricia Nguyen | N12: Disposed
A13: DSP-00007 | B13: SN12973570 | C13: Printer | D13: Ashley Jones | E13: 46052 | F13: Poor | G13: Yes | H13: Yes | I13: DOD 5220.22-M | J13: Metro E-Waste Partners | K13: No | M13: Robert Kim | N13: Certificate Missing
A14: DSP-00008 | B14: SN47521734 | C14: Desktop | D14: Tyler Rodriguez | E14: 46043 | F14: Poor | G14: Yes | H14: No | K14: No | M14: Robert Kim | N14: Pending Wipe
A15: DSP-00009 | B15: SN85262332 | C15: Mobile Phone | D15: Tracy Johnson | E15: 46048 | F15: Damaged | G15: Yes | H15: No | K15: No | M15: Daniel A. Cruz | N15: Pending Wipe
A16: DSP-00010 | B16: SN71494868 | C16: Scanner | D16: John Stark | E16: 46172 | F16: Fair | G16: Yes | H16: Yes | I16: DOD 5220.22-M | J16: EcoCycle IT Disposal | K16: No | M16: Patricia Nguyen | N16: Certificate Missing
A17: DSP-00011 | B17: SN02796181 | C17: Desktop | D17: David Wright | E17: 46156 | F17: Good | G17: Yes | H17: Yes | I17: NIST 800-88 Clear | J17: SecureShred Electronics | K17: No | M17: Daniel A. Cruz | N17: Certificate Missing
A18: DSP-00012 | B18: SN82801874 | C18: Printer | D18: Michael Velasquez | E18: 46104 | F18: Good | G18: Yes | H18: No | J18: Metro E-Waste Partners | K18: No | M18: Sandra Lopez | N18: Pending Wipe
A19: DSP-00013 | B19: SN85529386 | C19: Desktop | D19: Andrew Reeves | E19: 46185 | F19: Poor | G19: Yes | H19: No | J19: Metro E-Waste Partners | K19: No | M19: Robert Kim | N19: Pending Wipe
A20: DSP-00014 | B20: SN17786177 | C20: Desktop | D20: Martha Murphy | E20: 46178 | F20: Poor | G20: Yes | H20: No | J20: SecureShred Electronics | K20: No | M20: Patricia Nguyen | N20: Pending Wipe
A21: DSP-00015 | B21: SN66804869 | C21: Mobile Phone | D21: Lydia Lawrence | E21: 46059 | F21: Good | G21: Yes | H21: Yes | J21: EcoCycle IT Disposal | K21: Yes | L21: 46184 | M21: Patricia Nguyen | N21: Disposed
A22: DSP-00016 | B22: SN14052690 | C22: Mobile Phone | D22: Cynthia Bryant | E22: 46109 | F22: Good | G22: Yes | H22: Yes | K22: No | M22: Robert Kim | N22: Certificate Missing
A23: DSP-00017 | B23: SN05033171 | C23: Printer | D23: Melinda Reed | E23: 46039 | F23: Good | G23: Yes | H23: No | K23: No | M23: Daniel A. Cruz | N23: Pending Wipe
A24: DSP-00018 | B24: SN86179444 | C24: Printer | D24: Sara Williams | E24: 46033 | F24: Damaged | G24: No | H24: No | K24: No | M24: Sandra Lopez | N24: Hold for Review
A25: DSP-00019 | B25: SN21763683 | C25: Mobile Phone | D25: Daniel Smith | E25: 46154 | F25: Damaged | G25: No | H25: No | J25: SecureShred Electronics | K25: No | M25: Sandra Lopez | N25: Hold for Review
A26: DSP-00020 | B26: SN44126075 | C26: Mobile Phone | D26: Maria Daniels | E26: 46075 | F26: Good | G26: Yes | H26: No | J26: EcoCycle IT Disposal | K26: No | M26: Sandra Lopez | N26: Pending Wipe
A27: DSP-00021 | B27: SN51041890 | C27: Laptop | D27: Heather Gonzalez MD | E27: 46121 | F27: Poor | G27: Yes | H27: No | J27: EcoCycle IT Disposal | K27: No | M27: Daniel A. Cruz | N27: Pending Wipe
A28: DSP-00022 | B28: SN28577995 | C28: Monitor | D28: Ryan Lawson | E28: 46063 | F28: Poor | G28: Yes | H28: Yes | J28: SecureShred Electronics | K28: No | M28: Daniel A. Cruz | N28: Certificate Missing
A29: DSP-00023 | B29: SN18226284 | C29: Printer | D29: Jeffrey Williams | E29: 46069 | F29: Good | G29: Yes | H29: No | K29: No | M29: Daniel A. Cruz | N29: Pending Wipe
A30: DSP-00024 | B30: SN84618136 | C30: Scanner | D30: Barbara White | E30: 46052 | F30: Fair | G30: Yes | H30: No | J30: EcoCycle IT Disposal | K30: No | M30: Sandra Lopez | N30: Pending Wipe
A31: DSP-00025 | B31: SN44232109 | C31: Laptop | D31: Sara Harvey | E31: 46057 | F31: Non-Functional | G31: Yes | H31: Yes | J31: Metro E-Waste Partners | K31: No | M31: Patricia Nguyen | N31: Certificate Missing

Sheet Management Summary
A1: Management Summary
A2: v1.0.0 | Executive Overview | Reference Date: July 01, 2026
A3: 1. Inventory Health Highlights
A4: Total Inventory Value | C4: Aged Inventory Value | E4: Excess Inventory Value | G4: Transfer Candidates | I4: Markdown Candidates
A5: =SUM('Master Inventory'!N3:N122) | C5: =SUMIF('Master Inventory'!Q3:Q122,">180",'Master Inventory'!N3:N122) | E5: =SUMIF('Master Inventory'!U3:U122,"Excess",'Master Inventory'!N3:N122)+SUMIF('Master Inventory'!U3:U122,"Excess / Aged",'Master Inventory'!N3:N122) | G5: =COUNTIF('Master Inventory'!V3:V122,"Review Transfer")+COUNTIF('Master Inventory'!V3:V122,"Transfer or Markdown") | I5: =COUNTIF('Master Inventory'!V3:V122,"Markdown Review")+COUNTIF('Master Inventory'!V3:V122,"Transfer or Markdown")+COUNTIF('Master Inventory'!V3:V122,"Liquidate")
A7: 2. IT Asset Control Highlights
A8: Total IT Assets | C8: Assigned Assets | E8: Missing Assets | G8: Audit Exceptions | I8: Assets Pending Disposal
A9: =COUNTA('IT Asset Register'!A3:A122) | C9: =COUNTIF('IT Asset Register'!L3:L122,"Assigned") | E9: =COUNTIF('IT Asset Register'!L3:L122,"Missing") | G9: 20 | I9: =COUNTIF('Disposal Log'!N7:N31,"Pending Wipe")+COUNTIF('Disposal Log'!N7:N31,"Wiped")+COUNTIF('Disposal Log'!N7:N31,"Pending Vendor Pickup")+COUNTIF('Disposal Log'!N7:N31,"Certificate Missing")+COUNTIF('Disposal Log'!N7:N31,"Hold for Review")
A11: 3. Software License Risks
A12: Total Software Records | C12: Over-Assigned Licenses | E12: Renewals Due ≤ 90 Days | G12: Total Annual Software Cost
A13: =COUNTA('Software Licenses'!A7:A28) | C13: =COUNTIF('Software Licenses'!L7:L28,"Over-Assigned") | E13: =COUNTIF('Software Licenses'!H7:H28,"<=90") | G13: =SUM('Software Licenses'!K7:K28)
A15: 4. Disposal / Lifecycle Risks
A16: Pending Wipe | C16: Certificate Missing | E16: Disposed | G16: Hold for Review
A17: =COUNTIF('Disposal Log'!N7:N31,"Pending Wipe") | C17: =COUNTIF('Disposal Log'!N7:N31,"Certificate Missing") | E17: =COUNTIF('Disposal Log'!N7:N31,"Disposed") | G17: =COUNTIF('Disposal Log'!N7:N31,"Hold for Review")
A19: Executive Summaries
A20: Recommended Action Summary | D20: Audit Exception Summary | G20: Software Compliance Summary
A21: Monitor | B21: 39 | D21: Missing from Audit | E21: 4 | G21: Compliant | H21: 15
A22: Transfer or Markdown | B22: 34 | D22: Missing Asset Tag | E22: 4 | G22: Renewal Watch | H22: 5
A23: Replenish | B23: 21 | D23: Wrong User | E23: 4 | G23: Over-Assigned | H23: 1
A24: 5. Top Risks
A25: Top 5 Inventory Risks | E25: 3 | F25: Top 5 IT Asset Risks
A26: T-1019 | B26: Store-Brooklyn | C26: Excess / Aged | D26: 12783.33 | F26: DSK-00003 | G26: Desktop | H26: Missing — Audit Exception | I26: Store-Bronx
A27: T-1003 | B27: Store-Bronx | C27: Excess / Aged | D27: 12643.75 | F27: DSK-00098 | G27: Desktop | H27: Missing — Audit Exception | I27: DC-PA
A28: T-1023 | B28: DC-PA | C28: Excess / Aged | D28: 12572.1 | F28: LAP-00051 | G28: Laptop | H28: Missing — Audit Exception | I28: Store-Yonkers
A29: B-1055 | B29: Store-Brooklyn | C29: Excess / Aged | D29: 11654.87 | F29: MOB-00025 | G29: Mobile Phone | H29: Missing — Audit Exception | I29: Store-Manhattan
A30: B-1045 | B30: Store-Brooklyn | C30: Excess / Aged | D30: 11394.17 | F30: DSK-00057 | G30: Desktop | H30: In Repair — Service Backlog | I30: Store-Stamford
A32: 6. 30 / 60 / 90 Day Action Plan
A33: 30 Days | D33: 60 Days | G33: 90 Days
A34: • Validate asset and inventory records | D34: • Standardize audit and reconciliation procedures | G34: • Automate recurring reports
A35: • Review high-risk exceptions | D35: • Improve dashboard reporting | G35: • Build KPI review cadence
A36: • Confirm current reporting needs | D36: • Identify recurring inventory issues | G36: • Recommend process improvements
